Traceback (most recent call last):
  File "/Users/kt_imacpro/.pyenv/versions/3.8.5/lib/python3.8/site-packages/jupyter_cache/executors/utils.py", line 51, in single_nb_execution
    executenb(
  File "/Users/kt_imacpro/.pyenv/versions/3.8.5/lib/python3.8/site-packages/nbclient/client.py", line 1082, in execute
    return NotebookClient(nb=nb, resources=resources, km=km, **kwargs).execute()
  File "/Users/kt_imacpro/.pyenv/versions/3.8.5/lib/python3.8/site-packages/nbclient/util.py", line 74, in wrapped
    return just_run(coro(*args, **kwargs))
  File "/Users/kt_imacpro/.pyenv/versions/3.8.5/lib/python3.8/site-packages/nbclient/util.py", line 53, in just_run
    return loop.run_until_complete(coro)
  File "/Users/kt_imacpro/.pyenv/versions/3.8.5/lib/python3.8/asyncio/base_events.py", line 616, in run_until_complete
    return future.result()
  File "/Users/kt_imacpro/.pyenv/versions/3.8.5/lib/python3.8/site-packages/nbclient/client.py", line 535, in async_execute
    await self.async_execute_cell(
  File "/Users/kt_imacpro/.pyenv/versions/3.8.5/lib/python3.8/site-packages/nbclient/client.py", line 827, in async_execute_cell
    self._check_raise_for_error(cell, exec_reply)
  File "/Users/kt_imacpro/.pyenv/versions/3.8.5/lib/python3.8/site-packages/nbclient/client.py", line 735, in _check_raise_for_error
    raise CellExecutionError.from_cell_and_msg(cell, exec_reply['content'])
nbclient.exceptions.CellExecutionError: An error occurred while executing the following cell:
------------------
import re
with open('clinical.tsv') as f:
    header, *lines = f.readlines()
    data = {}
    for line in lines:
        cols = line.strip().split('\t')
        if cols[15] == 'Alive' and re.search(r'\d+', cols[47]): #cols[47] days_to_last_follow_up
            data.setdefault(cols[1], f'{int(cols[47]) // 30}\t0') 
        elif cols[15] == 'Dead' and re.search(r'\d+', cols[9]): #cols[9] days_to_death
            data.setdefault(cols[1], f'{int(cols[9]) // 30}\t1')
        else:
            print(line) #Ê¨†ÊêçÂÄ§„Åå„ÅÇ„Çå„Å∞Âá∫Âäõ„Åô„Çã
    
with open('clinical_edited.tsv', 'w') as out:
    print('T', 'E', sep='\t', file=out)
    for value in data.values():
        print(value, file=out)  
------------------

[0;31m---------------------------------------------------------------------------[0m
[0;31mFileNotFoundError[0m                         Traceback (most recent call last)
[0;32m<ipython-input-1-23b513c83311>[0m in [0;36m<module>[0;34m[0m
[1;32m      1[0m [0;32mimport[0m [0mre[0m[0;34m[0m[0;34m[0m[0m
[0;32m----> 2[0;31m [0;32mwith[0m [0mopen[0m[0;34m([0m[0;34m'clinical.tsv'[0m[0;34m)[0m [0;32mas[0m [0mf[0m[0;34m:[0m[0;34m[0m[0;34m[0m[0m
[0m[1;32m      3[0m     [0mheader[0m[0;34m,[0m [0;34m*[0m[0mlines[0m [0;34m=[0m [0mf[0m[0;34m.[0m[0mreadlines[0m[0;34m([0m[0;34m)[0m[0;34m[0m[0;34m[0m[0m
[1;32m      4[0m     [0mdata[0m [0;34m=[0m [0;34m{[0m[0;34m}[0m[0;34m[0m[0;34m[0m[0m
[1;32m      5[0m     [0;32mfor[0m [0mline[0m [0;32min[0m [0mlines[0m[0;34m:[0m[0;34m[0m[0;34m[0m[0m

[0;31mFileNotFoundError[0m: [Errno 2] No such file or directory: 'clinical.tsv'
FileNotFoundError: [Errno 2] No such file or directory: 'clinical.tsv'

